Workbook

Sheet Archetype_DB
A1: Build Name ▲ | B1: Position | C1: Height | D1: Weight | E1: Close Shot | F1: Driving Layup | G1: Driving Dunk | H1: Standing Dunk | I1: Post Control | J1: Midrange Shot | K1: Threepoint Shot | L1: Free Throw | M1: Pass Accuracy | N1: Ball Handle | O1: Speed With Ball | P1: Interior Defense | Q1: Perimeter Defense | R1: Steal | S1: Block | T1: Offensive Rebound | U1: Defensive Rebound | V1: Speed | W1: Agility | X1: Strength | Y1: Vertical | Z1: Season Index
A3: 2-Way 3-Level Scorer | B3: Point Guard | C3: 6'4" to 6'6" | D3: 180-214 | E3: 70-77 | F3: 71-80 | G3: 80-95 | H3: 25-57 | I3: 25-38 | J3: 85-92 | K3: 85-95 | L3: 65-99 | M3: 50-80 | N3: 75-83 | O3: 75-83 | P3: 45-70 | Q3: 85-95 | R3: 56-91 | S3: 40-74 | T3: 25-66 | U3: 50-55 | V3: 88-93 | W3: 79-90 | X3: 50-67 | Y3: 60-80 | Z3: 1
A4: 2-Way 3-Level Shot Creator | B4: Point Guard | C4: 6'2" to 6'7" | D4: 168-230 | E4: 70-83 | F4: 70-90 | G4: 25-93 | H4: 25-60 | I4: 32-51 | J4: 85-95 | K4: 83-96 | L4: 64-99 | M4: 61-85 | N4: 83-93 | O4: 75-91 | P4: 40-80 | Q4: 85-92 | R4: 55-89 | S4: 35-80 | T4: 25-70 | U4: 45-80 | V4: 75-91 | W4: 72-88 | X4: 45-75 | Y4: 56-83 | Z4: 1
A5: 2-Way 3PT Playmaker | B5: Point Guard | C5: 6'2" to 6'7" | D5: 178-218 | E5: 64-74 | F5: 71-80 | G5: 26-80 | H5: 25-29 | I5: 28-51 | J5: 79-83 | K5: 88-93 | L5: 66-99 | M5: 87-92 | N5: 82-94 | O5: 82-91 | P5: 44-60 | Q5: 85-91 | R5: 56-99 | S5: 35-61 | T5: 25-70 | U5: 45-57 | V5: 85-91 | W5: 77-87 | X5: 50-81 | Y5: 56-70 | Z5: 1
A6: 2-Way 3PT Shot Hunter | B6: Point Guard | C6: 6'2" to 6'7" | D6: 168-207 | E6: 63-85 | F6: 70-83 | G6: 25-81 | H6: 25-51 | I6: 32-53 | J6: 77-84 | K6: 85-94 | L6: 60-99 | M6: 60-85 | N6: 85-94 | O6: 75-94 | P6: 35-78 | Q6: 85-94 | R6: 55-93 | S6: 35-78 | T6: 25-62 | U6: 45-70 | V6: 85-94 | W6: 76-90 | X6: 45-84 | Y6: 60-83 | Z6: 1
A7: 2-Way 3PT Slasher | B7: Point Guard | C7: 6'1" to 6'7" | D7: 165-230 | E7: 64-83 | F7: 70-85 | G7: 60-94 | H7: 25-60 | I7: 30-60 | J7: 75-84 | K7: 83-94 | L7: 60-99 | M7: 60-85 | N7: 83-94 | O7: 71-94 | P7: 30-82 | Q7: 80-93 | R7: 50-93 | S7: 30-78 | T7: 25-75 | U7: 40-78 | V7: 80-94 | W7: 70-90 | X7: 40-81 | Y7: 60-85 | Z7: 1
A8: 2-Way 3PT Sniper | B8: Point Guard | C8: 6'1" to 6'6" | D8: 178-206 | E8: 68-76 | F8: 85-88 | G8: 25-80 | H8: 25-30 | I8: 31-46 | J8: 82-84 | K8: 92-94 | L8: 68-80 | M8: 65-87 | N8: 86-92 | O8: 80-91 | P8: 39-77 | Q8: 85-94 | R8: 60-91 | S8: 36-68 | T8: 25-35 | U8: 45-57 | V8: 85-91 | W8: 76-89 | X8: 47-74 | Y8: 56-70 | Z8: 1
A9: 2-Way 3PT-Creating Cleaner | B9: Point Guard | C9: 6'6" | D9: 215 | E9: 65 | F9: 80 | G9: 80 | H9: 40 | I9: 42 | J9: 79 | K9: 89 | L9: 65 | M9: 77 | N9: 86 | O9: 80 | P9: 78 | Q9: 92 | R9: 67 | S9: 74 | T9: 74 | U9: 80 | V9: 86 | W9: 80 | X9: 82 | Y9: 70 | Z9: 1
A10: 2-Way 3PT-Sniping High Flyer | B10: Point Guard | C10: 6'4" to 6'7" | D10: 190-211 | E10: 65-84 | F10: 62-80 | G10: 82-89 | H10: 33-51 | I10: 27-79 | J10: 77-84 | K10: 86-94 | L10: 62-91 | M10: 53-81 | N10: 70-84 | O10: 73-83 | P10: 46-79 | Q10: 85-95 | R10: 63-92 | S10: 41-62 | T10: 26-67 | U10: 50-75 | V10: 83-92 | W10: 83-93 | X10: 51-83 | Y10: 75-86 | Z10: 1
A11: 2-Way Blow-By Bully | B11: Point Guard | C11: 6'4" | D11: 214 | E11: 60 | F11: 70 | G11: 75 | H11: 25 | I11: 32 | J11: 73 | K11: 83 | L11: 70 | M11: 82 | N11: 81 | O11: 86 | P11: 53 | Q11: 96 | R11: 85 | S11: 46 | T11: 35 | U11: 56 | V11: 94 | W11: 90 | X11: 82 | Y11: 75 | Z11: 1
A12: 2-Way Blow-By Dual Finisher | B12: Point Guard | C12: 6'3" | D12: 213 | E12: 73 | F12: 88 | G12: 87 | H12: 32 | I12: 34 | J12: 73 | K12: 78 | L12: 77 | M12: 84 | N12: 86 | O12: 91 | P12: 43 | Q12: 91 | R12: 85 | S12: 41 | T12: 37 | U12: 60 | V12: 91 | W12: 83 | X12: 73 | Y12: 75 | Z12: 1
A13: 2-Way Blow-By High Flyer | B13: Point Guard | C13: 6'4" to 6'6" | D13: 180-210 | E13: 66-78 | F13: 75-81 | G13: 86-93 | H13: 37-64 | I13: 44-60 | J13: 80 | K13: 75-83 | L13: 58-77 | M13: 67-85 | N13: 86-90 | O13: 85-86 | P13: 67-83 | Q13: 91-92 | R13: 77-79 | S13: 55-69 | T13: 37-70 | U13: 55-63 | V13: 86-89 | W13: 74-84 | X13: 57-73 | Y13: 75-80 | Z13: 1
A14: 2-Way Bully Laymaking Cleaner | B14: Point Guard | C14: 6'7" | D14: 230 | E14: 80 | F14: 90 | G14: 47 | H14: 32 | I14: 77 | J14: 68 | K14: 78 | L14: 70 | M14: 85 | N14: 86 | O14: 81 | P14: 60 | Q14: 85 | R14: 60 | S14: 74 | T14: 55 | U14: 80 | V14: 85 | W14: 83 | X14: 84 | Y14: 77 | Z14: 1
A15: 2-Way Crafty 3-Level Dimer | B15: Point Guard | C15: 6'7" | D15: 180 | E15: 77 | F15: 85 | G15: 77 | H15: 48 | I15: 80 | J15: 87 | K15: 85 | L15: 78 | M15: 91 | N15: 81 | O15: 80 | P15: 71 | Q15: 85 | R15: 60 | S15: 45 | T15: 72 | U15: 78 | V15: 80 | W15: 78 | X15: 72 | Y15: 72 | Z15: 1
A16: 2-Way Crafty Mid-Range Slasher | B16: Point Guard | C16: 6'6" | D16: 210 | E16: 77 | F16: 85 | G16: 87 | H16: 37 | I16: 41 | J16: 92 | K16: 80 | L16: 88 | M16: 76 | N16: 86 | O16: 80 | P16: 60 | Q16: 85 | R16: 73 | S16: 75 | T16: 25 | U16: 50 | V16: 83 | W16: 80 | X16: 71 | Y16: 75 | Z16: 1
A17: 2-Way Disruptive High Flyer | B17: Point Guard | C17: 6'7" | D17: 203 | E17: 73 | F17: 80 | G17: 89 | H17: 40 | I17: 43 | J17: 71 | K17: 81 | L17: 81 | M17: 39 | N17: 64 | O17: 65 | P17: 80 | Q17: 92 | R17: 85 | S17: 87 | T17: 37 | U17: 62 | V17: 90 | W17: 88 | X17: 78 | Y17: 80 | Z17: 1
A18: 2-Way High-Flying Dime Dropper | B18: Point Guard | C18: 6'7" | D18: 189 | E18: 74 | F18: 75 | G18: 94 | H18: 49 | I18: 52 | J18: 34 | K18: 25 | L18: 45 | M18: 92 | N18: 82 | O18: 83 | P18: 80 | Q18: 94 | R18: 80 | S18: 84 | T18: 77 | U18: 80 | V18: 83 | W18: 80 | X18: 73 | Y18: 88 | Z18: 1
A19: 2-Way High-Flying Slasher | B19: Point Guard | C19: 6'6" | D19: 185-205 | E19: 73-84 | F19: 73-81 | G19: 87-93 | H19: 37-43 | I19: 40-48 | J19: 70-75 | K19: 80-83 | L19: 55-79 | M19: 75-85 | N19: 85-90 | O19: 75-80 | P19: 50-73 | Q19: 85-95 | R19: 61-85 | S19: 45-74 | T19: 30-74 | U19: 55-75 | V19: 80-91 | W19: 76-83 | X19: 51-64 | Y19: 70-85 | Z19: 1
A20: 2-Way Inside-Out Bully Slasher | B20: Point Guard | C20: 6'5" | D20: 230 | E20: 74 | F20: 85 | G20: 92 | H20: 38 | I20: 40 | J20: 77 | K20: 85 | L20: 89 | M20: 76 | N20: 86 | O20: 86 | P20: 60 | Q20: 85 | R20: 73 | S20: 68 | T20: 32 | U20: 55 | V20: 86 | W20: 80 | X20: 85 | Y20: 80 | Z20: 1
A21: 2-Way Inside-Out Creator | B21: Point Guard | C21: 6'0" to 6'5" | D21: 199-205 | E21: 83-89 | F21: 80-84 | G21: 74-89 | H21: 25 | I21: 39-85 | J21: 80-83 | K21: 83-92 | L21: 70-78 | M21: 74-85 | N21: 82-92 | O21: 86-91 | P21: 49-50 | Q21: 88-92 | R21: 59-85 | S21: 39-42 | T21: 36-62 | U21: 44-52 | V21: 88-91 | W21: 79-80 | X21: 73-75 | Y21: 65-73 | Z21: 1
A22: 2-Way Inside-Out Dime-Dropper | B22: Point Guard | C22: 6'6" | D22: 225 | E22: 65 | F22: 71 | G22: 83 | H22: 40 | I22: 40 | J22: 80 | K22: 89 | L22: 99 | M22: 90 | N22: 84 | O22: 75 | P22: 49 | Q22: 90 | R22: 79 | S22: 68 | T22: 44 | U22: 68 | V22: 85 | W22: 83 | X22: 73 | Y22: 75 | Z22: 1
A23: 2-Way Inside-Out Playmaker | B23: Point Guard | C23: 6'2" to 6'6" | D23: 175-218 | E23: 70-80 | F23: 75-90 | G23: 25-95 | H23: 25-50 | I23: 26-42 | J23: 75-85 | K23: 85-94 | L23: 75-99 | M23: 86-94 | N23: 82-92 | O23: 78-88 | P23: 35-61 | Q23: 80-91 | R23: 55-94 | S23: 33-68 | T23: 25-71 | U23: 40-56 | V23: 85-88 | W23: 80-90 | X23: 45-85 | Y23: 58-81 | Z23: 1
A24: 2-Way Inside-Out Scorer | B24: Point Guard | C24: 6'7" | D24: 205 | E24: 80 | F24: 90 | G24: 90 | H24: 40 | I24: 40 | J24: 75 | K24: 85 | L24: 63 | M24: 77 | N24: 80 | O24: 72 | P24: 80 | Q24: 85 | R24: 60 | S24: 64 | T24: 47 | U24: 72 | V24: 86 | W24: 80 | X24: 60 | Y24: 82 | Z24: 1
A25: 2-Way Inside-Out Slasher | B25: Point Guard | C25: 6'4" to 6'5" | D25: 175-203 | E25: 73-81 | F25: 85-90 | G25: 89-96 | H25: 35-45 | I25: 36-43 | J25: 79-82 | K25: 85-90 | L25: 63-88 | M25: 71-85 | N25: 86-93 | O25: 86-88 | P25: 35-51 | Q25: 85-90 | R25: 55-73 | S25: 35-50 | T25: 25-30 | U25: 45-50 | V25: 86-88 | W25: 77-83 | X25: 46-73 | Y25: 70-85 | Z25: 1
A26: 2-Way Iso Sniper | B26: Point Guard | C26: 6'1" to 6'7" | D26: 168-224 | E26: 70-80 | F26: 70-85 | G26: 25-81 | H26: 25-48 | I26: 25-67 | J26: 85-94 | K26: 87-99 | L26: 65-99 | M26: 60-85 | N26: 81-94 | O26: 80-91 | P26: 35-78 | Q26: 82-93 | R26: 55-95 | S26: 32-74 | T26: 25-65 | U26: 40-58 | V26: 85-92 | W26: 76-90 | X26: 42-71 | Y26: 55-77 | Z26: 1
A27: 2-Way Iso-Sniping Cleaner | B27: Point Guard | C27: 6'7" | D27: 219 | E27: 76 | F27: 71 | G27: 57 | H27: 31 | I27: 46 | J27: 91 | K27: 89 | L27: 99 | M27: 85 | N27: 86 | O27: 80 | P27: 55 | Q27: 90 | R27: 61 | S27: 46 | T27: 55 | U27: 80 | V27: 85 | W27: 83 | X27: 73 | Y27: 75 | Z27: 1
A28: 2-Way Mid-Paint Maestro Bully | B28: Point Guard | C28: 6'7" | D28: 215 | E28: 84 | F28: 94 | G28: 73 | H28: 25 | I28: 50 | J28: 87 | K28: 83 | L28: 84 | M28: 91 | N28: 81 | O28: 75 | P28: 60 | Q28: 85 | R28: 60 | S28: 74 | T28: 25 | U28: 49 | V28: 85 | W28: 77 | X28: 85 | Y28: 65 | Z28: 1
A29: 2-Way Mid-Paint Playmaker | B29: Point Guard | C29: 6'4" | D29: 212 | E29: 80 | F29: 91 | G29: 25 | H29: 25 | I29: 80 | J29: 94 | K29: 70 | L29: 76 | M29: 87 | N29: 86 | O29: 86 | P29: 55 | Q29: 87 | R29: 85 | S29: 37 | T29: 40 | U29: 47 | V29: 86 | W29: 85 | X29: 85 | Y29: 56 | Z29: 1
A30: 2-Way Mid-Post Creator | B30: Point Guard | C30: 6'4" | D30: 230 | E30: 82 | F30: 70 | G30: 89 | H30: 65 | I30: 87 | J30: 90 | K30: 85 | L30: 75 | M30: 78 | N30: 85 | O30: 75 | P30: 82 | Q30: 88 | R30: 80 | S30: 70 | T30: 78 | U30: 82 | V30: 85 | W30: 80 | X30: 85 | Y30: 82 | Z30: 1
A31: 2-Way Mid-Post High Flyer | B31: Point Guard | C31: 6'6" | D31: 230 | E31: 84 | F31: 71 | G31: 91 | H31: 41 | I31: 87 | J31: 90 | K31: 80 | L31: 66 | M31: 55 | N31: 80 | O31: 84 | P31: 77 | Q31: 85 | R31: 55 | S31: 74 | T31: 47 | U31: 57 | V31: 85 | W31: 86 | X31: 86 | Y31: 80 | Z31: 1
A32: 2-Way Mid-Post Playmaker | B32: Point Guard | C32: 6'7" | D32: 230 | E32: 89 | F32: 73 | G32: 29 | H32: 26 | I32: 92 | J32: 93 | K32: 62 | L32: 82 | M32: 88 | N32: 88 | O32: 81 | P32: 49 | Q32: 94 | R32: 64 | S32: 49 | T32: 55 | U32: 54 | V32: 85 | W32: 83 | X32: 69 | Y32: 55 | Z32: 1
A33: 2-Way Mid-Post Scorer | B33: Point Guard | C33: 6'7" | D33: 180 | E33: 90 | F33: 90 | G33: 79 | H33: 75 | I33: 80 | J33: 87 | K33: 81 | L33: 65 | M33: 70 | N33: 70 | O33: 70 | P33: 89 | Q33: 88 | R33: 70 | S33: 68 | T33: 51 | U33: 69 | V33: 91 | W33: 76 | X33: 69 | Y33: 61 | Z33: 1
A34: 2-Way Mid-Range High Flyer | B34: Point Guard | C34: 6'3" to 6'6" | D34: 180-225 | E34: 72-78 | F34: 71-80 | G34: 75-93 | H34: 25-40 | I34: 31-80 | J34: 87-92 | K34: 80-85 | L34: 64-99 | M34: 65-84 | N34: 85-92 | O34: 85-91 | P34: 35-78 | Q34: 85-92 | R34: 55-85 | S34: 35-74 | T34: 25-77 | U34: 45-74 | V34: 86-91 | W34: 71-87 | X34: 50-87 | Y34: 75-87 | Z34: 1
A35: 2-Way Mid-Range Menace | B35: Point Guard | C35: 6'3" to 6'7" | D35: 195-205 | E35: 75-78 | F35: 73-88 | G35: 54-80 | H35: 35-40 | I35: 39-70 | J35: 87-93 | K35: 80-83 | L35: 64-86 | M35: 71-79 | N35: 86-88 | O35: 75-90 | P35: 47-79 | Q35: 85-88 | R35: 73-87 | S35: 63-78 | T35: 33-74 | U35: 45-59 | V35: 85-93 | W35: 77-85 | X35: 58-80 | Y35: 60-82 | Z35: 1
A36: 2-Way Mid-Range Slasher | B36: Point Guard | C36: 6'2" to 6'7" | D36: 180-230 | E36: 74-85 | F36: 70-93 | G36: 73-93 | H36: 27-43 | I36: 30-62 | J36: 85-95 | K36: 60-84 | L36: 65-99 | M36: 61-85 | N36: 81-90 | O36: 75-86 | P36: 40-70 | Q36: 85-92 | R36: 60-88 | S36: 40-79 | T36: 25-70 | U36: 50-75 | V36: 80-90 | W36: 70-86 | X36: 50-75 | Y36: 60-80 | Z36: 1
A37: 2-Way Middy Playmaker | B37: Point Guard | C37: 6'7" | D37: 205 | E37: 77 | F37: 80 | G37: 80 | H37: 40 | I37: 45 | J37: 86 | K37: 80 | L37: 70 | M37: 95 | N37: 85 | O37: 81 | P37: 72 | Q37: 86 | R37: 80 | S37: 43 | T37: 36 | U37: 57 | V37: 81 | W37: 82 | X37: 61 | Y37: 65 | Z37: 1
A38: 2-Way Off-Screen Shooter | B38: Point Guard | C38: 5'10" to 6'7" | D38: 180-219 | E38: 74-81 | F38: 56-81 | G38: 25-70 | H38: 25-30 | I38: 25-55 | J38: 89-96 | K38: 85-99 | L38: 71-93 | M38: 35-82 | N38: 60-82 | O38: 65-82 | P38: 49-70 | Q38: 87-96 | R38: 72-96 | S38: 42-78 | T38: 26-39 | U38: 50-64 | V38: 85-91 | W38: 85-91 | X38: 60-85 | Y38: 55-74 | Z38: 1
A39: 2-Way Physical Laymaker | B39: Point Guard | C39: 6'7" | D39: 207 | E39: 83 | F39: 93 | G39: 70 | H39: 30 | I39: 51 | J39: 66 | K39: 75 | L39: 50 | M39: 82 | N39: 90 | O39: 82 | P39: 60 | Q39: 90 | R39: 61 | S39: 46 | T39: 27 | U39: 50 | V39: 90 | W39: 79 | X39: 85 | Y39: 75 | Z39: 1
A40: 2-Way Playmaking Bully Creator | B40: Point Guard | C40: 6'3" | D40: 213 | E40: 90 | F40: 80 | G40: 25 | H40: 25 | I40: 32 | J40: 85 | K40: 94 | L40: 75 | M40: 90 | N40: 86 | O40: 80 | P40: 76 | Q40: 85 | R40: 81 | S40: 47 | T40: 41 | U40: 58 | V40: 85 | W40: 78 | X40: 84 | Y40: 60 | Z40: 1
A41: 2-Way Playmaking Creator | B41: Point Guard | C41: 6'2" to 6'7" | D41: 196-215 | E41: 75-80 | F41: 70-75 | G41: 30-80 | H41: 25-30 | I41: 29-50 | J41: 87-93 | K41: 85-97 | L41: 65-75 | M41: 87 | N41: 85-90 | O41: 75-85 | P41: 45-70 | Q41: 85-95 | R41: 60-81 | S41: 35-75 | T41: 25-37 | U41: 45-55 | V41: 85-90 | W41: 85 | X41: 62-75 | Y41: 55-65 | Z41: 1
...

Sheet Percentiles
L1: Inches | M1: BBGM Hgt
L2: 66 | M2: 0
L3: 68 | M3: 8.33
L4: 70 | M4: 16.67
L5: 72 | M5: 25
L6: 74 | M6: 33.33
L7: 76 | M7: 41.67
L8: 78 | M8: 50
L9: 80 | M9: 58.33
L10: 82 | M10: 66.67
L11: 84 | M11: 75
L12: 86 | M12: 83.33
A19: 2K Percentiles
A20: Stat | B20: 1st | C20: 10th | D20: 25th | E20: 50th | F20: 75th | G20: 90th | H20: 95th | I20: 99th
A21: Close Shot | B21: =IFERROR(__xludf.DUMMYFUNCTION("PERCENTILE(INDEX(Archetype_DB!$A$2:$Z1000, 0, MATCH($A21, Archetype_DB!$A$1:$Z$1, 0)), VALUE(REGEXEXTRACT(B$20, ""\d+""))/100)"),64.35) -> 64.35 | C21: =IFERROR(__xludf.DUMMYFUNCTION("PERCENTILE(INDEX(Archetype_DB!$A$2:$Z1000, 0, MATCH($A21, Archetype_DB!$A$1:$Z$1, 0)), VALUE(REGEXEXTRACT(C$20, ""\d+""))/100)"),71.0) -> 71 | D21: =IFERROR(__xludf.DUMMYFUNCTION("PERCENTILE(INDEX(Archetype_DB!$A$2:$Z1000, 0, MATCH($A21, Archetype_DB!$A$1:$Z$1, 0)), VALUE(REGEXEXTRACT(D$20, ""\d+""))/100)"),75.0) -> 75 | E21: =IFERROR(__xludf.DUMMYFUNCTION("PERCENTILE(INDEX(Archetype_DB!$A$2:$Z1000, 0, MATCH($A21, Archetype_DB!$A$1:$Z$1, 0)), VALUE(REGEXEXTRACT(E$20, ""\d+""))/100)"),80.0) -> 80 | F21: =IFERROR(__xludf.DUMMYFUNCTION("PERCENTILE(INDEX(Archetype_DB!$A$2:$Z1000, 0, MATCH($A21, Archetype_DB!$A$1:$Z$1, 0)), VALUE(REGEXEXTRACT(F$20, ""\d+""))/100)"),84.0) -> 84 | G21: =IFERROR(__xludf.DUMMYFUNCTION("PERCENTILE(INDEX(Archetype_DB!$A$2:$Z1000, 0, MATCH($A21, Archetype_DB!$A$1:$Z$1, 0)), VALUE(REGEXEXTRACT(G$20, ""\d+""))/100)"),89.0) -> 89 | H21: =IFERROR(__xludf.DUMMYFUNCTION("PERCENTILE(INDEX(Archetype_DB!$A$2:$Z1000, 0, MATCH($A21, Archetype_DB!$A$1:$Z$1, 0)), VALUE(REGEXEXTRACT(H$20, ""\d+""))/100)"),92.0) -> 92 | I21: =IFERROR(__xludf.DUMMYFUNCTION("PERCENTILE(INDEX(Archetype_DB!$A$2:$Z1000, 0, MATCH($A21, Archetype_DB!$A$1:$Z$1, 0)), VALUE(REGEXEXTRACT(I$20, ""\d+""))/100)"),95.64999999999998) -> 95.65
A22: Driving Layup | B22: =IFERROR(__xludf.DUMMYFUNCTION("PERCENTILE(INDEX(Archetype_DB!$A$2:$Z1000, 0, MATCH($A22, Archetype_DB!$A$1:$Z$1, 0)), VALUE(REGEXEXTRACT(B$20, ""\d+""))/100)"),50.36) -> 50.36 | C22: =IFERROR(__xludf.DUMMYFUNCTION("PERCENTILE(INDEX(Archetype_DB!$A$2:$Z1000, 0, MATCH($A22, Archetype_DB!$A$1:$Z$1, 0)), VALUE(REGEXEXTRACT(C$20, ""\d+""))/100)"),60.0) -> 60 | D22: =IFERROR(__xludf.DUMMYFUNCTION("PERCENTILE(INDEX(Archetype_DB!$A$2:$Z1000, 0, MATCH($A22, Archetype_DB!$A$1:$Z$1, 0)), VALUE(REGEXEXTRACT(D$20, ""\d+""))/100)"),70.0) -> 70 | E22: =IFERROR(__xludf.DUMMYFUNCTION("PERCENTILE(INDEX(Archetype_DB!$A$2:$Z1000, 0, MATCH($A22, Archetype_DB!$A$1:$Z$1, 0)), VALUE(REGEXEXTRACT(E$20, ""\d+""))/100)"),75.0) -> 75 | F22: =IFERROR(__xludf.DUMMYFUNCTION("PERCENTILE(INDEX(Archetype_DB!$A$2:$Z1000, 0, MATCH($A22, Archetype_DB!$A$1:$Z$1, 0)), VALUE(REGEXEXTRACT(F$20, ""\d+""))/100)"),81.0) -> 81 | G22: =IFERROR(__xludf.DUMMYFUNCTION("PERCENTILE(INDEX(Archetype_DB!$A$2:$Z1000, 0, MATCH($A22, Archetype_DB!$A$1:$Z$1, 0)), VALUE(REGEXEXTRACT(G$20, ""\d+""))/100)"),88.0) -> 88 | H22: =IFERROR(__xludf.DUMMYFUNCTION("PERCENTILE(INDEX(Archetype_DB!$A$2:$Z1000, 0, MATCH($A22, Archetype_DB!$A$1:$Z$1, 0)), VALUE(REGEXEXTRACT(H$20, ""\d+""))/100)"),90.0) -> 90 | I22: =IFERROR(__xludf.DUMMYFUNCTION("PERCENTILE(INDEX(Archetype_DB!$A$2:$Z1000, 0, MATCH($A22, Archetype_DB!$A$1:$Z$1, 0)), VALUE(REGEXEXTRACT(I$20, ""\d+""))/100)"),94.63999999999999) -> 94.64
A23: Driving Dunk | B23: =IFERROR(__xludf.DUMMYFUNCTION("PERCENTILE(INDEX(Archetype_DB!$A$2:$Z1000, 0, MATCH($A23, Archetype_DB!$A$1:$Z$1, 0)), VALUE(REGEXEXTRACT(B$20, ""\d+""))/100)"),30.0) -> 30 | C23: =IFERROR(__xludf.DUMMYFUNCTION("PERCENTILE(INDEX(Archetype_DB!$A$2:$Z1000, 0, MATCH($A23, Archetype_DB!$A$1:$Z$1, 0)), VALUE(REGEXEXTRACT(C$20, ""\d+""))/100)"),65.0) -> 65 | D23: =IFERROR(__xludf.DUMMYFUNCTION("PERCENTILE(INDEX(Archetype_DB!$A$2:$Z1000, 0, MATCH($A23, Archetype_DB!$A$1:$Z$1, 0)), VALUE(REGEXEXTRACT(D$20, ""\d+""))/100)"),74.0) -> 74 | E23: =IFERROR(__xludf.DUMMYFUNCTION("PERCENTILE(INDEX(Archetype_DB!$A$2:$Z1000, 0, MATCH($A23, Archetype_DB!$A$1:$Z$1, 0)), VALUE(REGEXEXTRACT(E$20, ""\d+""))/100)"),83.0) -> 83 | F23: =IFERROR(__xludf.DUMMYFUNCTION("PERCENTILE(INDEX(Archetype_DB!$A$2:$Z1000, 0, MATCH($A23, Archetype_DB!$A$1:$Z$1, 0)), VALUE(REGEXEXTRACT(F$20, ""\d+""))/100)"),89.0) -> 89 | G23: =IFERROR(__xludf.DUMMYFUNCTION("PERCENTILE(INDEX(Archetype_DB!$A$2:$Z1000, 0, MATCH($A23, Archetype_DB!$A$1:$Z$1, 0)), VALUE(REGEXEXTRACT(G$20, ""\d+""))/100)"),93.0) -> 93 | H23: =IFERROR(__xludf.DUMMYFUNCTION("PERCENTILE(INDEX(Archetype_DB!$A$2:$Z1000, 0, MATCH($A23, Archetype_DB!$A$1:$Z$1, 0)), VALUE(REGEXEXTRACT(H$20, ""\d+""))/100)"),94.0) -> 94 | I23: =IFERROR(__xludf.DUMMYFUNCTION("PERCENTILE(INDEX(Archetype_DB!$A$2:$Z1000, 0, MATCH($A23, Archetype_DB!$A$1:$Z$1, 0)), VALUE(REGEXEXTRACT(I$20, ""\d+""))/100)"),96.50999999999999) -> 96.51
A24: Standing Dunk | B24: =IFERROR(__xludf.DUMMYFUNCTION("PERCENTILE(INDEX(Archetype_DB!$A$2:$Z1000, 0, MATCH($A24, Archetype_DB!$A$1:$Z$1, 0)), VALUE(REGEXEXTRACT(B$20, ""\d+""))/100)"),25.0) -> 25 | C24: =IFERROR(__xludf.DUMMYFUNCTION("PERCENTILE(INDEX(Archetype_DB!$A$2:$Z1000, 0, MATCH($A24, Archetype_DB!$A$1:$Z$1, 0)), VALUE(REGEXEXTRACT(C$20, ""\d+""))/100)"),39.0) -> 39 | D24: =IFERROR(__xludf.DUMMYFUNCTION("PERCENTILE(INDEX(Archetype_DB!$A$2:$Z1000, 0, MATCH($A24, Archetype_DB!$A$1:$Z$1, 0)), VALUE(REGEXEXTRACT(D$20, ""\d+""))/100)"),51.0) -> 51 | E24: =IFERROR(__xludf.DUMMYFUNCTION("PERCENTILE(INDEX(Archetype_DB!$A$2:$Z1000, 0, MATCH($A24, Archetype_DB!$A$1:$Z$1, 0)), VALUE(REGEXEXTRACT(E$20, ""\d+""))/100)"),72.0) -> 72 | F24: =IFERROR(__xludf.DUMMYFUNCTION("PERCENTILE(INDEX(Archetype_DB!$A$2:$Z1000, 0, MATCH($A24, Archetype_DB!$A$1:$Z$1, 0)), VALUE(REGEXEXTRACT(F$20, ""\d+""))/100)"),85.0) -> 85 | G24: =IFERROR(__xludf.DUMMYFUNCTION("PERCENTILE(INDEX(Archetype_DB!$A$2:$Z1000, 0, MATCH($A24, Archetype_DB!$A$1:$Z$1, 0)), VALUE(REGEXEXTRACT(G$20, ""\d+""))/100)"),90.0) -> 90 | H24: =IFERROR(__xludf.DUMMYFUNCTION("PERCENTILE(INDEX(Archetype_DB!$A$2:$Z1000, 0, MATCH($A24, Archetype_DB!$A$1:$Z$1, 0)), VALUE(REGEXEXTRACT(H$20, ""\d+""))/100)"),90.0) -> 90 | I24: =IFERROR(__xludf.DUMMYFUNCTION("PERCENTILE(INDEX(Archetype_DB!$A$2:$Z1000, 0, MATCH($A24, Archetype_DB!$A$1:$Z$1, 0)), VALUE(REGEXEXTRACT(I$20, ""\d+""))/100)"),95.0) -> 95
A25: Post Control | B25: =IFERROR(__xludf.DUMMYFUNCTION("PERCENTILE(INDEX(Archetype_DB!$A$2:$Z1000, 0, MATCH($A25, Archetype_DB!$A$1:$Z$1, 0)), VALUE(REGEXEXTRACT(B$20, ""\d+""))/100)"),30.0) -> 30 | C25: =IFERROR(__xludf.DUMMYFUNCTION("PERCENTILE(INDEX(Archetype_DB!$A$2:$Z1000, 0, MATCH($A25, Archetype_DB!$A$1:$Z$1, 0)), VALUE(REGEXEXTRACT(C$20, ""\d+""))/100)"),43.3) -> 43.3 | D25: =IFERROR(__xludf.DUMMYFUNCTION("PERCENTILE(INDEX(Archetype_DB!$A$2:$Z1000, 0, MATCH($A25, Archetype_DB!$A$1:$Z$1, 0)), VALUE(REGEXEXTRACT(D$20, ""\d+""))/100)"),50.0) -> 50 | E25: =IFERROR(__xludf.DUMMYFUNCTION("PERCENTILE(INDEX(Archetype_DB!$A$2:$Z1000, 0, MATCH($A25, Archetype_DB!$A$1:$Z$1, 0)), VALUE(REGEXEXTRACT(E$20, ""\d+""))/100)"),60.0) -> 60 | F25: =IFERROR(__xludf.DUMMYFUNCTION("PERCENTILE(INDEX(Archetype_DB!$A$2:$Z1000, 0, MATCH($A25, Archetype_DB!$A$1:$Z$1, 0)), VALUE(REGEXEXTRACT(F$20, ""\d+""))/100)"),79.0) -> 79 | G25: =IFERROR(__xludf.DUMMYFUNCTION("PERCENTILE(INDEX(Archetype_DB!$A$2:$Z1000, 0, MATCH($A25, Archetype_DB!$A$1:$Z$1, 0)), VALUE(REGEXEXTRACT(G$20, ""\d+""))/100)"),87.0) -> 87 | H25: =IFERROR(__xludf.DUMMYFUNCTION("PERCENTILE(INDEX(Archetype_DB!$A$2:$Z1000, 0, MATCH($A25, Archetype_DB!$A$1:$Z$1, 0)), VALUE(REGEXEXTRACT(H$20, ""\d+""))/100)"),88.0) -> 88 | I25: =IFERROR(__xludf.DUMMYFUNCTION("PERCENTILE(INDEX(Archetype_DB!$A$2:$Z1000, 0, MATCH($A25, Archetype_DB!$A$1:$Z$1, 0)), VALUE(REGEXEXTRACT(I$20, ""\d+""))/100)"),93.0) -> 93
A26: Midrange Shot | B26: =IFERROR(__xludf.DUMMYFUNCTION("PERCENTILE(INDEX(Archetype_DB!$A$2:$Z1000, 0, MATCH($A26, Archetype_DB!$A$1:$Z$1, 0)), VALUE(REGEXEXTRACT(B$20, ""\d+""))/100)"),38.0) -> 38 | C26: =IFERROR(__xludf.DUMMYFUNCTION("PERCENTILE(INDEX(Archetype_DB!$A$2:$Z1000, 0, MATCH($A26, Archetype_DB!$A$1:$Z$1, 0)), VALUE(REGEXEXTRACT(C$20, ""\d+""))/100)"),70.0) -> 70 | D26: =IFERROR(__xludf.DUMMYFUNCTION("PERCENTILE(INDEX(Archetype_DB!$A$2:$Z1000, 0, MATCH($A26, Archetype_DB!$A$1:$Z$1, 0)), VALUE(REGEXEXTRACT(D$20, ""\d+""))/100)"),74.0) -> 74 | E26: =IFERROR(__xludf.DUMMYFUNCTION("PERCENTILE(INDEX(Archetype_DB!$A$2:$Z1000, 0, MATCH($A26, Archetype_DB!$A$1:$Z$1, 0)), VALUE(REGEXEXTRACT(E$20, ""\d+""))/100)"),80.0) -> 80 | F26: =IFERROR(__xludf.DUMMYFUNCTION("PERCENTILE(INDEX(Archetype_DB!$A$2:$Z1000, 0, MATCH($A26, Archetype_DB!$A$1:$Z$1, 0)), VALUE(REGEXEXTRACT(F$20, ""\d+""))/100)"),86.0) -> 86 | G26: =IFERROR(__xludf.DUMMYFUNCTION("PERCENTILE(INDEX(Archetype_DB!$A$2:$Z1000, 0, MATCH($A26, Archetype_DB!$A$1:$Z$1, 0)), VALUE(REGEXEXTRACT(G$20, ""\d+""))/100)"),90.0) -> 90 | H26: =IFERROR(__xludf.DUMMYFUNCTION("PERCENTILE(INDEX(Archetype_DB!$A$2:$Z1000, 0, MATCH($A26, Archetype_DB!$A$1:$Z$1, 0)), VALUE(REGEXEXTRACT(H$20, ""\d+""))/100)"),92.0) -> 92 | I26: =IFERROR(__xludf.DUMMYFUNCTION("PERCENTILE(INDEX(Archetype_DB!$A$2:$Z1000, 0, MATCH($A26, Archetype_DB!$A$1:$Z$1, 0)), VALUE(REGEXEXTRACT(I$20, ""\d+""))/100)"),95.51999999999998) -> 95.52
A27: Threepoint Shot | B27: =IFERROR(__xludf.DUMMYFUNCTION("PERCENTILE(INDEX(Archetype_DB!$A$2:$Z1000, 0, MATCH($A27, Archetype_DB!$A$1:$Z$1, 0)), VALUE(REGEXEXTRACT(B$20, ""\d+""))/100)"),25.0) -> 25 | C27: =IFERROR(__xludf.DUMMYFUNCTION("PERCENTILE(INDEX(Archetype_DB!$A$2:$Z1000, 0, MATCH($A27, Archetype_DB!$A$1:$Z$1, 0)), VALUE(REGEXEXTRACT(C$20, ""\d+""))/100)"),70.2) -> 70.2 | D27: =IFERROR(__xludf.DUMMYFUNCTION("PERCENTILE(INDEX(Archetype_DB!$A$2:$Z1000, 0, MATCH($A27, Archetype_DB!$A$1:$Z$1, 0)), VALUE(REGEXEXTRACT(D$20, ""\d+""))/100)"),80.0) -> 80 | E27: =IFERROR(__xludf.DUMMYFUNCTION("PERCENTILE(INDEX(Archetype_DB!$A$2:$Z1000, 0, MATCH($A27, Archetype_DB!$A$1:$Z$1, 0)), VALUE(REGEXEXTRACT(E$20, ""\d+""))/100)"),82.0) -> 82 | F27: =IFERROR(__xludf.DUMMYFUNCTION("PERCENTILE(INDEX(Archetype_DB!$A$2:$Z1000, 0, MATCH($A27, Archetype_DB!$A$1:$Z$1, 0)), VALUE(REGEXEXTRACT(F$20, ""\d+""))/100)"),85.0) -> 85 | G27: =IFERROR(__xludf.DUMMYFUNCTION("PERCENTILE(INDEX(Archetype_DB!$A$2:$Z1000, 0, MATCH($A27, Archetype_DB!$A$1:$Z$1, 0)), VALUE(REGEXEXTRACT(G$20, ""\d+""))/100)"),90.0) -> 90 | H27: =IFERROR(__xludf.DUMMYFUNCTION("PERCENTILE(INDEX(Archetype_DB!$A$2:$Z1000, 0, MATCH($A27, Archetype_DB!$A$1:$Z$1, 0)), VALUE(REGEXEXTRACT(H$20, ""\d+""))/100)"),90.0) -> 90 | I27: =IFERROR(__xludf.DUMMYFUNCTION("PERCENTILE(INDEX(Archetype_DB!$A$2:$Z1000, 0, MATCH($A27, Archetype_DB!$A$1:$Z$1, 0)), VALUE(REGEXEXTRACT(I$20, ""\d+""))/100)"),95.38) -> 95.38
A28: Free Throw | B28: =IFERROR(__xludf.DUMMYFUNCTION("PERCENTILE(INDEX(Archetype_DB!$A$2:$Z1000, 0, MATCH($A28, Archetype_DB!$A$1:$Z$1, 0)), VALUE(REGEXEXTRACT(B$20, ""\d+""))/100)"),39.0) -> 39 | C28: =IFERROR(__xludf.DUMMYFUNCTION("PERCENTILE(INDEX(Archetype_DB!$A$2:$Z1000, 0, MATCH($A28, Archetype_DB!$A$1:$Z$1, 0)), VALUE(REGEXEXTRACT(C$20, ""\d+""))/100)"),56.0) -> 56 | D28: =IFERROR(__xludf.DUMMYFUNCTION("PERCENTILE(INDEX(Archetype_DB!$A$2:$Z1000, 0, MATCH($A28, Archetype_DB!$A$1:$Z$1, 0)), VALUE(REGEXEXTRACT(D$20, ""\d+""))/100)"),61.0) -> 61 | E28: =IFERROR(__xludf.DUMMYFUNCTION("PERCENTILE(INDEX(Archetype_DB!$A$2:$Z1000, 0, MATCH($A28, Archetype_DB!$A$1:$Z$1, 0)), VALUE(REGEXEXTRACT(E$20, ""\d+""))/100)"),70.0) -> 70 | F28: =IFERROR(__xludf.DUMMYFUNCTION("PERCENTILE(INDEX(Archetype_DB!$A$2:$Z1000, 0, MATCH($A28, Archetype_DB!$A$1:$Z$1, 0)), VALUE(REGEXEXTRACT(F$20, ""\d+""))/100)"),78.0) -> 78 | G28: =IFERROR(__xludf.DUMMYFUNCTION("PERCENTILE(INDEX(Archetype_DB!$A$2:$Z1000, 0, MATCH($A28, Archetype_DB!$A$1:$Z$1, 0)), VALUE(REGEXEXTRACT(G$20, ""\d+""))/100)"),85.0) -> 85 | H28: =IFERROR(__xludf.DUMMYFUNCTION("PERCENTILE(INDEX(Archetype_DB!$A$2:$Z1000, 0, MATCH($A28, Archetype_DB!$A$1:$Z$1, 0)), VALUE(REGEXEXTRACT(H$20, ""\d+""))/100)"),91.0) -> 91 | I28: =IFERROR(__xludf.DUMMYFUNCTION("PERCENTILE(INDEX(Archetype_DB!$A$2:$Z1000, 0, MATCH($A28, Archetype_DB!$A$1:$Z$1, 0)), VALUE(REGEXEXTRACT(I$20, ""\d+""))/100)"),98.85000000000002) -> 98.85
A29: Pass Accuracy | B29: =IFERROR(__xludf.DUMMYFUNCTION("PERCENTILE(INDEX(Archetype_DB!$A$2:$Z1000, 0, MATCH($A29, Archetype_DB!$A$1:$Z$1, 0)), VALUE(REGEXEXTRACT(B$20, ""\d+""))/100)"),25.0) -> 25 | C29: =IFERROR(__xludf.DUMMYFUNCTION("PERCENTILE(INDEX(Archetype_DB!$A$2:$Z1000, 0, MATCH($A29, Archetype_DB!$A$1:$Z$1, 0)), VALUE(REGEXEXTRACT(C$20, ""\d+""))/100)"),60.0) -> 60 | D29: =IFERROR(__xludf.DUMMYFUNCTION("PERCENTILE(INDEX(Archetype_DB!$A$2:$Z1000, 0, MATCH($A29, Archetype_DB!$A$1:$Z$1, 0)), VALUE(REGEXEXTRACT(D$20, ""\d+""))/100)"),70.0) -> 70 | E29: =IFERROR(__xludf.DUMMYFUNCTION("PERCENTILE(INDEX(Archetype_DB!$A$2:$Z1000, 0, MATCH($A29, Archetype_DB!$A$1:$Z$1, 0)), VALUE(REGEXEXTRACT(E$20, ""\d+""))/100)"),76.0) -> 76 | F29: =IFERROR(__xludf.DUMMYFUNCTION("PERCENTILE(INDEX(Archetype_DB!$A$2:$Z1000, 0, MATCH($A29, Archetype_DB!$A$1:$Z$1, 0)), VALUE(REGEXEXTRACT(F$20, ""\d+""))/100)"),85.0) -> 85 | G29: =IFERROR(__xludf.DUMMYFUNCTION("PERCENTILE(INDEX(Archetype_DB!$A$2:$Z1000, 0, MATCH($A29, Archetype_DB!$A$1:$Z$1, 0)), VALUE(REGEXEXTRACT(G$20, ""\d+""))/100)"),87.0) -> 87 | H29: =IFERROR(__xludf.DUMMYFUNCTION("PERCENTILE(INDEX(Archetype_DB!$A$2:$Z1000, 0, MATCH($A29, Archetype_DB!$A$1:$Z$1, 0)), VALUE(REGEXEXTRACT(H$20, ""\d+""))/100)"),91.0) -> 91 | I29: =IFERROR(__xludf.DUMMYFUNCTION("PERCENTILE(INDEX(Archetype_DB!$A$2:$Z1000, 0, MATCH($A29, Archetype_DB!$A$1:$Z$1, 0)), VALUE(REGEXEXTRACT(I$20, ""\d+""))/100)"),95.0) -> 95
A30: Ball Handle | B30: =IFERROR(__xludf.DUMMYFUNCTION("PERCENTILE(INDEX(Archetype_DB!$A$2:$Z1000, 0, MATCH($A30, Archetype_DB!$A$1:$Z$1, 0)), VALUE(REGEXEXTRACT(B$20, ""\d+""))/100)"),38.9) -> 38.9 | C30: =IFERROR(__xludf.DUMMYFUNCTION("PERCENTILE(INDEX(Archetype_DB!$A$2:$Z1000, 0, MATCH($A30, Archetype_DB!$A$1:$Z$1, 0)), VALUE(REGEXEXTRACT(C$20, ""\d+""))/100)"),48.0) -> 48 | D30: =IFERROR(__xludf.DUMMYFUNCTION("PERCENTILE(INDEX(Archetype_DB!$A$2:$Z1000, 0, MATCH($A30, Archetype_DB!$A$1:$Z$1, 0)), VALUE(REGEXEXTRACT(D$20, ""\d+""))/100)"),60.0) -> 60 | E30: =IFERROR(__xludf.DUMMYFUNCTION("PERCENTILE(INDEX(Archetype_DB!$A$2:$Z1000, 0, MATCH($A30, Archetype_DB!$A$1:$Z$1, 0)), VALUE(REGEXEXTRACT(E$20, ""\d+""))/100)"),75.0) -> 75 | F30: =IFERROR(__xludf.DUMMYFUNCTION("PERCENTILE(INDEX(Archetype_DB!$A$2:$Z1000, 0, MATCH($A30, Archetype_DB!$A$1:$Z$1, 0)), VALUE(REGEXEXTRACT(F$20, ""\d+""))/100)"),81.0) -> 81 | G30: =IFERROR(__xludf.DUMMYFUNCTION("PERCENTILE(INDEX(Archetype_DB!$A$2:$Z1000, 0, MATCH($A30, Archetype_DB!$A$1:$Z$1, 0)), VALUE(REGEXEXTRACT(G$20, ""\d+""))/100)"),86.0) -> 86 | H30: =IFERROR(__xludf.DUMMYFUNCTION("PERCENTILE(INDEX(Archetype_DB!$A$2:$Z1000, 0, MATCH($A30, Archetype_DB!$A$1:$Z$1, 0)), VALUE(REGEXEXTRACT(H$20, ""\d+""))/100)"),86.0) -> 86 | I30: =IFERROR(__xludf.DUMMYFUNCTION("PERCENTILE(INDEX(Archetype_DB!$A$2:$Z1000, 0, MATCH($A30, Archetype_DB!$A$1:$Z$1, 0)), VALUE(REGEXEXTRACT(I$20, ""\d+""))/100)"),92.54999999999995) -> 92.55
A31: Speed With Ball | B31: =IFERROR(__xludf.DUMMYFUNCTION("PERCENTILE(INDEX(Archetype_DB!$A$2:$Z1000, 0, MATCH($A31, Archetype_DB!$A$1:$Z$1, 0)), VALUE(REGEXEXTRACT(B$20, ""\d+""))/100)"),25.0) -> 25 | C31: =IFERROR(__xludf.DUMMYFUNCTION("PERCENTILE(INDEX(Archetype_DB!$A$2:$Z1000, 0, MATCH($A31, Archetype_DB!$A$1:$Z$1, 0)), VALUE(REGEXEXTRACT(C$20, ""\d+""))/100)"),41.0) -> 41 | D31: =IFERROR(__xludf.DUMMYFUNCTION("PERCENTILE(INDEX(Archetype_DB!$A$2:$Z1000, 0, MATCH($A31, Archetype_DB!$A$1:$Z$1, 0)), VALUE(REGEXEXTRACT(D$20, ""\d+""))/100)"),55.0) -> 55 | E31: =IFERROR(__xludf.DUMMYFUNCTION("PERCENTILE(INDEX(Archetype_DB!$A$2:$Z1000, 0, MATCH($A31, Archetype_DB!$A$1:$Z$1, 0)), VALUE(REGEXEXTRACT(E$20, ""\d+""))/100)"),68.0) -> 68 | F31: =IFERROR(__xludf.DUMMYFUNCTION("PERCENTILE(INDEX(Archetype_DB!$A$2:$Z1000, 0, MATCH($A31, Archetype_DB!$A$1:$Z$1, 0)), VALUE(REGEXEXTRACT(F$20, ""\d+""))/100)"),75.0) -> 75 | G31: =IFERROR(__xludf.DUMMYFUNCTION("PERCENTILE(INDEX(Archetype_DB!$A$2:$Z1000, 0, MATCH($A31, Archetype_DB!$A$1:$Z$1, 0)), VALUE(REGEXEXTRACT(G$20, ""\d+""))/100)"),80.0) -> 80 | H31: =IFERROR(__xludf.DUMMYFUNCTION("PERCENTILE(INDEX(Archetype_DB!$A$2:$Z1000, 0, MATCH($A31, Archetype_DB!$A$1:$Z$1, 0)), VALUE(REGEXEXTRACT(H$20, ""\d+""))/100)"),84.89999999999998) -> 84.9 | I31: =IFERROR(__xludf.DUMMYFUNCTION("PERCENTILE(INDEX(Archetype_DB!$A$2:$Z1000, 0, MATCH($A31, Archetype_DB!$A$1:$Z$1, 0)), VALUE(REGEXEXTRACT(I$20, ""\d+""))/100)"),88.58000000000004) -> 88.58
A32: Interior Defense | B32: =IFERROR(__xludf.DUMMYFUNCTION("PERCENTILE(INDEX(Archetype_DB!$A$2:$Z1000, 0, MATCH($A32, Archetype_DB!$A$1:$Z$1, 0)), VALUE(REGEXEXTRACT(B$20, ""\d+""))/100)"),34.08) -> 34.08 | C32: =IFERROR(__xludf.DUMMYFUNCTION("PERCENTILE(INDEX(Archetype_DB!$A$2:$Z1000, 0, MATCH($A32, Archetype_DB!$A$1:$Z$1, 0)), VALUE(REGEXEXTRACT(C$20, ""\d+""))/100)"),60.0) -> 60 | D32: =IFERROR(__xludf.DUMMYFUNCTION("PERCENTILE(INDEX(Archetype_DB!$A$2:$Z1000, 0, MATCH($A32, Archetype_DB!$A$1:$Z$1, 0)), VALUE(REGEXEXTRACT(D$20, ""\d+""))/100)"),70.0) -> 70 | E32: =IFERROR(__xludf.DUMMYFUNCTION("PERCENTILE(INDEX(Archetype_DB!$A$2:$Z1000, 0, MATCH($A32, Archetype_DB!$A$1:$Z$1, 0)), VALUE(REGEXEXTRACT(E$20, ""\d+""))/100)"),80.0) -> 80 | F32: =IFERROR(__xludf.DUMMYFUNCTION("PERCENTILE(INDEX(Archetype_DB!$A$2:$Z1000, 0, MATCH($A32, Archetype_DB!$A$1:$Z$1, 0)), VALUE(REGEXEXTRACT(F$20, ""\d+""))/100)"),84.0) -> 84 | G32: =IFERROR(__xludf.DUMMYFUNCTION("PERCENTILE(INDEX(Archetype_DB!$A$2:$Z1000, 0, MATCH($A32, Archetype_DB!$A$1:$Z$1, 0)), VALUE(REGEXEXTRACT(G$20, ""\d+""))/100)"),88.0) -> 88 | H32: =IFERROR(__xludf.DUMMYFUNCTION("PERCENTILE(INDEX(Archetype_DB!$A$2:$Z1000, 0, MATCH($A32, Archetype_DB!$A$1:$Z$1, 0)), VALUE(REGEXEXTRACT(H$20, ""\d+""))/100)"),90.0) -> 90 | I32: =IFERROR(__xludf.DUMMYFUNCTION("PERCENTILE(INDEX(Archetype_DB!$A$2:$Z1000, 0, MATCH($A32, Archetype_DB!$A$1:$Z$1, 0)), VALUE(REGEXEXTRACT(I$20, ""\d+""))/100)"),92.92000000000007) -> 92.92
A33: Perimeter Defense | B33: =IFERROR(__xludf.DUMMYFUNCTION("PERCENTILE(INDEX(Archetype_DB!$A$2:$Z1000, 0, MATCH($A33, Archetype_DB!$A$1:$Z$1, 0)), VALUE(REGEXEXTRACT(B$20, ""\d+""))/100)"),35.0) -> 35 | C33: =IFERROR(__xludf.DUMMYFUNCTION("PERCENTILE(INDEX(Archetype_DB!$A$2:$Z1000, 0, MATCH($A33, Archetype_DB!$A$1:$Z$1, 0)), VALUE(REGEXEXTRACT(C$20, ""\d+""))/100)"),42.7) -> 42.7 | D33: =IFERROR(__xludf.DUMMYFUNCTION("PERCENTILE(INDEX(Archetype_DB!$A$2:$Z1000, 0, MATCH($A33, Archetype_DB!$A$1:$Z$1, 0)), VALUE(REGEXEXTRACT(D$20, ""\d+""))/100)"),61.0) -> 61 | E33: =IFERROR(__xludf.DUMMYFUNCTION("PERCENTILE(INDEX(Archetype_DB!$A$2:$Z1000, 0, MATCH($A33, Archetype_DB!$A$1:$Z$1, 0)), VALUE(REGEXEXTRACT(E$20, ""\d+""))/100)"),74.0) -> 74 | F33: =IFERROR(__xludf.DUMMYFUNCTION("PERCENTILE(INDEX(Archetype_DB!$A$2:$Z1000, 0, MATCH($A33, Archetype_DB!$A$1:$Z$1, 0)), VALUE(REGEXEXTRACT(F$20, ""\d+""))/100)"),82.0) -> 82 | G33: =IFERROR(__xludf.DUMMYFUNCTION("PERCENTILE(INDEX(Archetype_DB!$A$2:$Z1000, 0, MATCH($A33, Archetype_DB!$A$1:$Z$1, 0)), VALUE(REGEXEXTRACT(G$20, ""\d+""))/100)"),87.0) -> 87 | H33: =IFERROR(__xludf.DUMMYFUNCTION("PERCENTILE(INDEX(Archetype_DB!$A$2:$Z1000, 0, MATCH($A33, Archetype_DB!$A$1:$Z$1, 0)), VALUE(REGEXEXTRACT(H$20, ""\d+""))/100)"),92.0) -> 92 | I33: =IFERROR(__xludf.DUMMYFUNCTION("PERCENTILE(INDEX(Archetype_DB!$A$2:$Z1000, 0, MATCH($A33, Archetype_DB!$A$1:$Z$1, 0)), VALUE(REGEXEXTRACT(I$20, ""\d+""))/100)"),94.0) -> 94
A34: Steal | B34: =IFERROR(__xludf.DUMMYFUNCTION("PERCENTILE(INDEX(Archetype_DB!$A$2:$Z1000, 0, MATCH($A34, Archetype_DB!$A$1:$Z$1, 0)), VALUE(REGEXEXTRACT(B$20, ""\d+""))/100)"),33.0) -> 33 | C34: =IFERROR(__xludf.DUMMYFUNCTION("PERCENTILE(INDEX(Archetype_DB!$A$2:$Z1000, 0, MATCH($A34, Archetype_DB!$A$1:$Z$1, 0)), VALUE(REGEXEXTRACT(C$20, ""\d+""))/100)"),40.0) -> 40 | D34: =IFERROR(__xludf.DUMMYFUNCTION("PERCENTILE(INDEX(Archetype_DB!$A$2:$Z1000, 0, MATCH($A34, Archetype_DB!$A$1:$Z$1, 0)), VALUE(REGEXEXTRACT(D$20, ""\d+""))/100)"),48.0) -> 48 | E34: =IFERROR(__xludf.DUMMYFUNCTION("PERCENTILE(INDEX(Archetype_DB!$A$2:$Z1000, 0, MATCH($A34, Archetype_DB!$A$1:$Z$1, 0)), VALUE(REGEXEXTRACT(E$20, ""\d+""))/100)"),60.0) -> 60 | F34: =IFERROR(__xludf.DUMMYFUNCTION("PERCENTILE(INDEX(Archetype_DB!$A$2:$Z1000, 0, MATCH($A34, Archetype_DB!$A$1:$Z$1, 0)), VALUE(REGEXEXTRACT(F$20, ""\d+""))/100)"),75.0) -> 75 | G34: =IFERROR(__xludf.DUMMYFUNCTION("PERCENTILE(INDEX(Archetype_DB!$A$2:$Z1000, 0, MATCH($A34, Archetype_DB!$A$1:$Z$1, 0)), VALUE(REGEXEXTRACT(G$20, ""\d+""))/100)"),85.0) -> 85 | H34: =IFERROR(__xludf.DUMMYFUNCTION("PERCENTILE(INDEX(Archetype_DB!$A$2:$Z1000, 0, MATCH($A34, Archetype_DB!$A$1:$Z$1, 0)), VALUE(REGEXEXTRACT(H$20, ""\d+""))/100)"),89.0) -> 89 | I34: =IFERROR(__xludf.DUMMYFUNCTION("PERCENTILE(INDEX(Archetype_DB!$A$2:$Z1000, 0, MATCH($A34, Archetype_DB!$A$1:$Z$1, 0)), VALUE(REGEXEXTRACT(I$20, ""\d+""))/100)"),94.0) -> 94
A35: Block | B35: =IFERROR(__xludf.DUMMYFUNCTION("PERCENTILE(INDEX(Archetype_DB!$A$2:$Z1000, 0, MATCH($A35, Archetype_DB!$A$1:$Z$1, 0)), VALUE(REGEXEXTRACT(B$20, ""\d+""))/100)"),30.0) -> 30 | C35: =IFERROR(__xludf.DUMMYFUNCTION("PERCENTILE(INDEX(Archetype_DB!$A$2:$Z1000, 0, MATCH($A35, Archetype_DB!$A$1:$Z$1, 0)), VALUE(REGEXEXTRACT(C$20, ""\d+""))/100)"),50.0) -> 50 | D35: =IFERROR(__xludf.DUMMYFUNCTION("PERCENTILE(INDEX(Archetype_DB!$A$2:$Z1000, 0, MATCH($A35, Archetype_DB!$A$1:$Z$1, 0)), VALUE(REGEXEXTRACT(D$20, ""\d+""))/100)"),74.0) -> 74 | E35: =IFERROR(__xludf.DUMMYFUNCTION("PERCENTILE(INDEX(Archetype_DB!$A$2:$Z1000, 0, MATCH($A35, Archetype_DB!$A$1:$Z$1, 0)), VALUE(REGEXEXTRACT(E$20, ""\d+""))/100)"),80.0) -> 80 | F35: =IFERROR(__xludf.DUMMYFUNCTION("PERCENTILE(INDEX(Archetype_DB!$A$2:$Z1000, 0, MATCH($A35, Archetype_DB!$A$1:$Z$1, 0)), VALUE(REGEXEXTRACT(F$20, ""\d+""))/100)"),86.25) -> 86.25 | G35: =IFERROR(__xludf.DUMMYFUNCTION("PERCENTILE(INDEX(Archetype_DB!$A$2:$Z1000, 0, MATCH($A35, Archetype_DB!$A$1:$Z$1, 0)), VALUE(REGEXEXTRACT(G$20, ""\d+""))/100)"),93.0) -> 93 | H35: =IFERROR(__xludf.DUMMYFUNCTION("PERCENTILE(INDEX(Archetype_DB!$A$2:$Z1000, 0, MATCH($A35, Archetype_DB!$A$1:$Z$1, 0)), VALUE(REGEXEXTRACT(H$20, ""\d+""))/100)"),93.0) -> 93 | I35: =IFERROR(__xludf.DUMMYFUNCTION("PERCENTILE(INDEX(Archetype_DB!$A$2:$Z1000, 0, MATCH($A35, Archetype_DB!$A$1:$Z$1, 0)), VALUE(REGEXEXTRACT(I$20, ""\d+""))/100)"),95.0) -> 95
A36: Offensive Rebound | B36: =IFERROR(__xludf.DUMMYFUNCTION("PERCENTILE(INDEX(Archetype_DB!$A$2:$Z1000, 0, MATCH($A36, Archetype_DB!$A$1:$Z$1, 0)), VALUE(REGEXEXTRACT(B$20, ""\d+""))/100)"),25.0) -> 25 | C36: =IFERROR(__xludf.DUMMYFUNCTION("PERCENTILE(INDEX(Archetype_DB!$A$2:$Z1000, 0, MATCH($A36, Archetype_DB!$A$1:$Z$1, 0)), VALUE(REGEXEXTRACT(C$20, ""\d+""))/100)"),39.0) -> 39 | D36: =IFERROR(__xludf.DUMMYFUNCTION("PERCENTILE(INDEX(Archetype_DB!$A$2:$Z1000, 0, MATCH($A36, Archetype_DB!$A$1:$Z$1, 0)), VALUE(REGEXEXTRACT(D$20, ""\d+""))/100)"),59.0) -> 59 | E36: =IFERROR(__xludf.DUMMYFUNCTION("PERCENTILE(INDEX(Archetype_DB!$A$2:$Z1000, 0, MATCH($A36, Archetype_DB!$A$1:$Z$1, 0)), VALUE(REGEXEXTRACT(E$20, ""\d+""))/100)"),74.0) -> 74 | F36: =IFERROR(__xludf.DUMMYFUNCTION("PERCENTILE(INDEX(Archetype_DB!$A$2:$Z1000, 0, MATCH($A36, Archetype_DB!$A$1:$Z$1, 0)), VALUE(REGEXEXTRACT(F$20, ""\d+""))/100)"),84.0) -> 84 | G36: =IFERROR(__xludf.DUMMYFUNCTION("PERCENTILE(INDEX(Archetype_DB!$A$2:$Z1000, 0, MATCH($A36, Archetype_DB!$A$1:$Z$1, 0)), VALUE(REGEXEXTRACT(G$20, ""\d+""))/100)"),92.0) -> 92 | H36: =IFERROR(__xludf.DUMMYFUNCTION("PERCENTILE(INDEX(Archetype_DB!$A$2:$Z1000, 0, MATCH($A36, Archetype_DB!$A$1:$Z$1, 0)), VALUE(REGEXEXTRACT(H$20, ""\d+""))/100)"),94.0) -> 94 | I36: =IFERROR(__xludf.DUMMYFUNCTION("PERCENTILE(INDEX(Archetype_DB!$A$2:$Z1000, 0, MATCH($A36, Archetype_DB!$A$1:$Z$1, 0)), VALUE(REGEXEXTRACT(I$20, ""\d+""))/100)"),97.0) -> 97
A37: Defensive Rebound | B37: =IFERROR(__xludf.DUMMYFUNCTION("PERCENTILE(INDEX(Archetype_DB!$A$2:$Z1000, 0, MATCH($A37, Archetype_DB!$A$1:$Z$1, 0)), VALUE(REGEXEXTRACT(B$20, ""\d+""))/100)"),39.16) -> 39.16 | C37: =IFERROR(__xludf.DUMMYFUNCTION("PERCENTILE(INDEX(Archetype_DB!$A$2:$Z1000, 0, MATCH($A37, Archetype_DB!$A$1:$Z$1, 0)), VALUE(REGEXEXTRACT(C$20, ""\d+""))/100)"),55.0) -> 55 | D37: =IFERROR(__xludf.DUMMYFUNCTION("PERCENTILE(INDEX(Archetype_DB!$A$2:$Z1000, 0, MATCH($A37, Archetype_DB!$A$1:$Z$1, 0)), VALUE(REGEXEXTRACT(D$20, ""\d+""))/100)"),70.0) -> 70 | E37: =IFERROR(__xludf.DUMMYFUNCTION("PERCENTILE(INDEX(Archetype_DB!$A$2:$Z1000, 0, MATCH($A37, Archetype_DB!$A$1:$Z$1, 0)), VALUE(REGEXEXTRACT(E$20, ""\d+""))/100)"),81.0) -> 81 | F37: =IFERROR(__xludf.DUMMYFUNCTION("PERCENTILE(INDEX(Archetype_DB!$A$2:$Z1000, 0, MATCH($A37, Archetype_DB!$A$1:$Z$1, 0)), VALUE(REGEXEXTRACT(F$20, ""\d+""))/100)"),90.0) -> 90 | G37: =IFERROR(__xludf.DUMMYFUNCTION("PERCENTILE(INDEX(Archetype_DB!$A$2:$Z1000, 0, MATCH($A37, Archetype_DB!$A$1:$Z$1, 0)), VALUE(REGEXEXTRACT(G$20, ""\d+""))/100)"),94.0) -> 94 | H37: =IFERROR(__xludf.DUMMYFUNCTION("PERCENTILE(INDEX(Archetype_DB!$A$2:$Z1000, 0, MATCH($A37, Archetype_DB!$A$1:$Z$1, 0)), VALUE(REGEXEXTRACT(H$20, ""\d+""))/100)"),95.0) -> 95 | I37: =IFERROR(__xludf.DUMMYFUNCTION("PERCENTILE(INDEX(Archetype_DB!$A$2:$Z1000, 0, MATCH($A37, Archetype_DB!$A$1:$Z$1, 0)), VALUE(REGEXEXTRACT(I$20, ""\d+""))/100)"),97.0) -> 97
A38: Speed | B38: =IFERROR(__xludf.DUMMYFUNCTION("PERCENTILE(INDEX(Archetype_DB!$A$2:$Z1000, 0, MATCH($A38, Archetype_DB!$A$1:$Z$1, 0)), VALUE(REGEXEXTRACT(B$20, ""\d+""))/100)"),50.0) -> 50 | C38: =IFERROR(__xludf.DUMMYFUNCTION("PERCENTILE(INDEX(Archetype_DB!$A$2:$Z1000, 0, MATCH($A38, Archetype_DB!$A$1:$Z$1, 0)), VALUE(REGEXEXTRACT(C$20, ""\d+""))/100)"),65.0) -> 65 | D38: =IFERROR(__xludf.DUMMYFUNCTION("PERCENTILE(INDEX(Archetype_DB!$A$2:$Z1000, 0, MATCH($A38, Archetype_DB!$A$1:$Z$1, 0)), VALUE(REGEXEXTRACT(D$20, ""\d+""))/100)"),71.0) -> 71 | E38: =IFERROR(__xludf.DUMMYFUNCTION("PERCENTILE(INDEX(Archetype_DB!$A$2:$Z1000, 0, MATCH($A38, Archetype_DB!$A$1:$Z$1, 0)), VALUE(REGEXEXTRACT(E$20, ""\d+""))/100)"),80.0) -> 80 | F38: =IFERROR(__xludf.DUMMYFUNCTION("PERCENTILE(INDEX(Archetype_DB!$A$2:$Z1000, 0, MATCH($A38, Archetype_DB!$A$1:$Z$1, 0)), VALUE(REGEXEXTRACT(F$20, ""\d+""))/100)"),84.0) -> 84 | G38: =IFERROR(__xludf.DUMMYFUNCTION("PERCENTILE(INDEX(Archetype_DB!$A$2:$Z1000, 0, MATCH($A38, Archetype_DB!$A$1:$Z$1, 0)), VALUE(REGEXEXTRACT(G$20, ""\d+""))/100)"),87.0) -> 87 | H38: =IFERROR(__xludf.DUMMYFUNCTION("PERCENTILE(INDEX(Archetype_DB!$A$2:$Z1000, 0, MATCH($A38, Archetype_DB!$A$1:$Z$1, 0)), VALUE(REGEXEXTRACT(H$20, ""\d+""))/100)"),90.0) -> 90 | I38: =IFERROR(__xludf.DUMMYFUNCTION("PERCENTILE(INDEX(Archetype_DB!$A$2:$Z1000, 0, MATCH($A38, Archetype_DB!$A$1:$Z$1, 0)), VALUE(REGEXEXTRACT(I$20, ""\d+""))/100)"),93.0) -> 93
A39: Agility | B39: =IFERROR(__xludf.DUMMYFUNCTION("PERCENTILE(INDEX(Archetype_DB!$A$2:$Z1000, 0, MATCH($A39, Archetype_DB!$A$1:$Z$1, 0)), VALUE(REGEXEXTRACT(B$20, ""\d+""))/100)"),38.0) -> 38 | C39: =IFERROR(__xludf.DUMMYFUNCTION("PERCENTILE(INDEX(Archetype_DB!$A$2:$Z1000, 0, MATCH($A39, Archetype_DB!$A$1:$Z$1, 0)), VALUE(REGEXEXTRACT(C$20, ""\d+""))/100)"),51.0) -> 51 | D39: =IFERROR(__xludf.DUMMYFUNCTION("PERCENTILE(INDEX(Archetype_DB!$A$2:$Z1000, 0, MATCH($A39, Archetype_DB!$A$1:$Z$1, 0)), VALUE(REGEXEXTRACT(D$20, ""\d+""))/100)"),61.0) -> 61 | E39: =IFERROR(__xludf.DUMMYFUNCTION("PERCENTILE(INDEX(Archetype_DB!$A$2:$Z1000, 0, MATCH($A39, Archetype_DB!$A$1:$Z$1, 0)), VALUE(REGEXEXTRACT(E$20, ""\d+""))/100)"),74.0) -> 74 | F39: =IFERROR(__xludf.DUMMYFUNCTION("PERCENTILE(INDEX(Archetype_DB!$A$2:$Z1000, 0, MATCH($A39, Archetype_DB!$A$1:$Z$1, 0)), VALUE(REGEXEXTRACT(F$20, ""\d+""))/100)"),80.0) -> 80 | G39: =IFERROR(__xludf.DUMMYFUNCTION("PERCENTILE(INDEX(Archetype_DB!$A$2:$Z1000, 0, MATCH($A39, Archetype_DB!$A$1:$Z$1, 0)), VALUE(REGEXEXTRACT(G$20, ""\d+""))/100)"),83.0) -> 83 | H39: =IFERROR(__xludf.DUMMYFUNCTION("PERCENTILE(INDEX(Archetype_DB!$A$2:$Z1000, 0, MATCH($A39, Archetype_DB!$A$1:$Z$1, 0)), VALUE(REGEXEXTRACT(H$20, ""\d+""))/100)"),85.0) -> 85 | I39: =IFERROR(__xludf.DUMMYFUNCTION("PERCENTILE(INDEX(Archetype_DB!$A$2:$Z1000, 0, MATCH($A39, Archetype_DB!$A$1:$Z$1, 0)), VALUE(REGEXEXTRACT(I$20, ""\d+""))/100)"),88.63) -> 88.63
A40: Strength | B40: =IFERROR(__xludf.DUMMYFUNCTION("PERCENTILE(INDEX(Archetype_DB!$A$2:$Z1000, 0, MATCH($A40, Archetype_DB!$A$1:$Z$1, 0)), VALUE(REGEXEXTRACT(B$20, ""\d+""))/100)"),47.0) -> 47 | C40: =IFERROR(__xludf.DUMMYFUNCTION("PERCENTILE(INDEX(Archetype_DB!$A$2:$Z1000, 0, MATCH($A40, Archetype_DB!$A$1:$Z$1, 0)), VALUE(REGEXEXTRACT(C$20, ""\d+""))/100)"),65.0) -> 65 | D40: =IFERROR(__xludf.DUMMYFUNCTION("PERCENTILE(INDEX(Archetype_DB!$A$2:$Z1000, 0, MATCH($A40, Archetype_DB!$A$1:$Z$1, 0)), VALUE(REGEXEXTRACT(D$20, ""\d+""))/100)"),73.0) -> 73 | E40: =IFERROR(__xludf.DUMMYFUNCTION("PERCENTILE(INDEX(Archetype_DB!$A$2:$Z1000, 0, MATCH($A40, Archetype_DB!$A$1:$Z$1, 0)), VALUE(REGEXEXTRACT(E$20, ""\d+""))/100)"),83.0) -> 83 | F40: =IFERROR(__xludf.DUMMYFUNCTION("PERCENTILE(INDEX(Archetype_DB!$A$2:$Z1000, 0, MATCH($A40, Archetype_DB!$A$1:$Z$1, 0)), VALUE(REGEXEXTRACT(F$20, ""\d+""))/100)"),86.0) -> 86 | G40: =IFERROR(__xludf.DUMMYFUNCTION("PERCENTILE(INDEX(Archetype_DB!$A$2:$Z1000, 0, MATCH($A40, Archetype_DB!$A$1:$Z$1, 0)), VALUE(REGEXEXTRACT(G$20, ""\d+""))/100)"),91.0) -> 91 | H40: =IFERROR(__xludf.DUMMYFUNCTION("PERCENTILE(INDEX(Archetype_DB!$A$2:$Z1000, 0, MATCH($A40, Archetype_DB!$A$1:$Z$1, 0)), VALUE(REGEXEXTRACT(H$20, ""\d+""))/100)"),91.19999999999993) -> 91.2 | I40: =IFERROR(__xludf.DUMMYFUNCTION("PERCENTILE(INDEX(Archetype_DB!$A$2:$Z1000, 0, MATCH($A40, Archetype_DB!$A$1:$Z$1, 0)), VALUE(REGEXEXTRACT(I$20, ""\d+""))/100)"),95.0) -> 95
A41: Vertical | B41: =IFERROR(__xludf.DUMMYFUNCTION("PERCENTILE(INDEX(Archetype_DB!$A$2:$Z1000, 0, MATCH($A41, Archetype_DB!$A$1:$Z$1, 0)), VALUE(REGEXEXTRACT(B$20, ""\d+""))/100)"),55.43) -> 55.43 | C41: =IFERROR(__xludf.DUMMYFUNCTION("PERCENTILE(INDEX(Archetype_DB!$A$2:$Z1000, 0, MATCH($A41, Archetype_DB!$A$1:$Z$1, 0)), VALUE(REGEXEXTRACT(C$20, ""\d+""))/100)"),70.0) -> 70 | D41: =IFERROR(__xludf.DUMMYFUNCTION("PERCENTILE(INDEX(Archetype_DB!$A$2:$Z1000, 0, MATCH($A41, Archetype_DB!$A$1:$Z$1, 0)), VALUE(REGEXEXTRACT(D$20, ""\d+""))/100)"),75.0) -> 75 | E41: =IFERROR(__xludf.DUMMYFUNCTION("PERCENTILE(INDEX(Archetype_DB!$A$2:$Z1000, 0, MATCH($A41, Archetype_DB!$A$1:$Z$1, 0)), VALUE(REGEXEXTRACT(E$20, ""\d+""))/100)"),80.0) -> 80 | F41: =IFERROR(__xludf.DUMMYFUNCTION("PERCENTILE(INDEX(Archetype_DB!$A$2:$Z1000, 0, MATCH($A41, Archetype_DB!$A$1:$Z$1, 0)), VALUE(REGEXEXTRACT(F$20, ""\d+""))/100)"),83.0) -> 83 | G41: =IFERROR(__xludf.DUMMYFUNCTION("PERCENTILE(INDEX(Archetype_DB!$A$2:$Z1000, 0, MATCH($A41, Archetype_DB!$A$1:$Z$1, 0)), VALUE(REGEXEXTRACT(G$20, ""\d+""))/100)"),86.0) -> 86 | H41: =IFERROR(__xludf.DUMMYFUNCTION("PERCENTILE(INDEX(Archetype_DB!$A$2:$Z1000, 0, MATCH($A41, Archetype_DB!$A$1:$Z$1, 0)), VALUE(REGEXEXTRACT(H$20, ""\d+""))/100)"),88.0) -> 88 | I41: =IFERROR(__xludf.DUMMYFUNCTION("PERCENTILE(INDEX(Archetype_DB!$A$2:$Z1000, 0, MATCH($A41, Archetype_DB!$A$1:$Z$1, 0)), VALUE(REGEXEXTRACT(I$20, ""\d+""))/100)"),90.57000000000005) -> 90.57
A42: OIQ | B42: 25 | C42: 60 | D42: 70 | E42: 76 | F42: 85 | G42: 87 | H42: 91 | I42: 95
A44: Stat | B44: 1st | C44: 10th | D44: 25th | E44: 50th | F44: 75th | G44: 90th | H44: 95th | I44: 99th
A45: Hgt | B45: 23 | C45: 33 | D45: 40 | E45: 47 | F45: 55 | G45: 62 | H45: 66 | I45: 74
A46: Stre | B46: 23 | C46: 39 | D46: 44 | E46: 49 | F46: 55 | G46: 63 | H46: 68 | I46: 78
A47: Spd | B47: 32 | C47: 42 | D47: 46 | E47: 52 | F47: 60 | G47: 68 | H47: 72 | I47: 82
...

Sheet Archetype_Finder
A1: Hgt | B1: Stre | C1: Spd | D1: Jmp | E1: Endu | F1: Ins | G1: Dnk | H1: FT | I1: Mid | J1: TP | K1: OIQ | L1: DIQ | M1: Drb | N1: Pss | O1: Reb | Q1: Close Shot | R1: Driving Layup | S1: Driving Dunk | U1: Post Control | V1: Midrange Shot | W1: Threepoint Shot | X1: Free Throw | Y1: Pass Accuracy | Z1: Ball Handle | AA1: Speed With Ball | AB1: OIQ | AC1: Interior Defense | AD1: Perimeter Defense | AG1: Offensive Rebound | AH1: Defensive Rebound | AI1: Speed | AJ1: Agility | AK1: Strength | AL1: Vertical | AM1: Magnitude | AN1: User Height (Inches)
A2: 40 | B2: 66 | C2: 52 | D2: 58 | E2: 64 | F2: 45 | G2: 60 | H2: 65 | I2: 64 | J2: 72 | K2: 75 | L2: 66 | M2: 56 | N2: 51 | O2: 51 | Q2: {=LET(x, 0.6*F2 + 0.25*B2 + 0.15*K2, x_range, Percentiles!$B$50:$I$50, y_range, Translation_Matrix!$B$12:$I$12, matchIdx, IFNA(MATCH(x, x_range, 1), 1), colIdx, MIN(7, MAX(1, matchIdx)), IF(x <= INDEX(x_range, 1), INDEX(y_range, 1), IF(x >= INDEX(x_range, 8), INDEX(y_range, 8), FORECAST(x, OFFSET(INDEX(y_range, 1), 0, colIdx - 1, 1, 2), OFFSET(INDEX(x_range, 1), 0, colIdx - 1, 1, 2)))))} -> 88.305556 | R2: {=LET(x, 0.5*F2 + 0.3*C2 + 0.2*D2, x_range, Percentiles!$B$50:$I$50, y_range, Translation_Matrix!$B$13:$I$13, matchIdx, IFNA(MATCH(x, x_range, 1), 1), colIdx, MIN(7, MAX(1, matchIdx)), IF(x <= INDEX(x_range, 1), INDEX(y_range, 1), IF(x >= INDEX(x_range, 8), INDEX(y_range, 8), FORECAST(x, OFFSET(INDEX(y_range, 1), 0, colIdx - 1, 1, 2), OFFSET(INDEX(x_range, 1), 0, colIdx - 1, 1, 2)))))} -> 83.1 | S2: {=LET(x, LET(drv, 0.5*G2 + 0.3*C2 + 0.2*D2, std, 0.65*G2 + 0.25*A2 + 0.1*D2, IF($AN$2 > 80, (drv + std) / 2, drv)), x_range, Percentiles!$B$51:$I$51, y_range, Translation_Matrix!$B$16:$I$16, matchIdx, IFNA(MATCH(x, x_range, 1), 1), colIdx, MIN(7, MAX(1, matchIdx)), IF(x <= INDEX(x_range, 1), INDEX(y_range, 1), IF(x >= INDEX(x_range, 8), INDEX(y_range, 8), FORECAST(x, OFFSET(INDEX(y_range, 1), 0, colIdx - 1, 1, 2), OFFSET(INDEX(x_range, 1), 0, colIdx - 1, 1, 2)))))} -> 89.533333 | U2: {=LET(x, 0.65*F2 + 0.2*B2 + 0.15*K2, x_range, Percentiles!$B$50:$I$50, y_range, Translation_Matrix!$B$14:$I$14, matchIdx, IFNA(MATCH(x, x_range, 1), 1), colIdx, MIN(7, MAX(1, matchIdx)), IF(x <= INDEX(x_range, 1), INDEX(y_range, 1), IF(x >= INDEX(x_range, 8), INDEX(y_range, 8), FORECAST(x, OFFSET(INDEX(y_range, 1), 0, colIdx - 1, 1, 2), OFFSET(INDEX(x_range, 1), 0, colIdx - 1, 1, 2)))))} -> 84.955556 | V2: {=LET(x, (0.7*I2)+(0.15*K2)+(0.15*H2), x_range, Percentiles!$B$53:$I$53, y_range, Translation_Matrix!$B$21:$I$21, matchIdx, IFNA(MATCH(x, x_range, 1), 1), colIdx, MIN(7, MAX(1, matchIdx)), IF(x <= INDEX(x_range, 1), INDEX(y_range, 1), IF(x >= INDEX(x_range, 8), INDEX(y_range, 8), FORECAST(x, OFFSET(INDEX(y_range, 1), 0, colIdx - 1, 1, 2), OFFSET(INDEX(x_range, 1), 0, colIdx - 1, 1, 2)))))} -> 89.563636 | W2: {=LET(x, 1*J2, x_range, Percentiles!$B$54:$I$54, y_range, Translation_Matrix!$B$23:$I$23, matchIdx, IFNA(MATCH(x, x_range, 1), 1), colIdx, MIN(7, MAX(1, matchIdx)), IF(x <= INDEX(x_range, 1), INDEX(y_range, 1), IF(x >= INDEX(x_range, 8), INDEX(y_range, 8), FORECAST(x, OFFSET(INDEX(y_range, 1), 0, colIdx - 1, 1, 2), OFFSET(INDEX(x_range, 1), 0, colIdx - 1, 1, 2)))))} -> 90.35582 | X2: {=LET(x, 1*H2, x_range, Percentiles!$B$52:$I$52, y_range, Translation_Matrix!$B$19:$I$19, matchIdx, IFNA(MATCH(x, x_range, 1), 1), colIdx, MIN(7, MAX(1, matchIdx)), IF(x <= INDEX(x_range, 1), INDEX(y_range, 1), IF(x >= INDEX(x_range, 8), INDEX(y_range, 8), FORECAST(x, OFFSET(INDEX(y_range, 1), 0, colIdx - 1, 1, 2), OFFSET(INDEX(x_range, 1), 0, colIdx - 1, 1, 2)))))} -> 88 | Y2: {=LET(x, 0.5*N2 + 0.5*K2, x_range, Percentiles!$B$58:$I$58, y_range, Translation_Matrix!$B$34:$I$34, matchIdx, IFNA(MATCH(x, x_range, 1), 1), colIdx, MIN(7, MAX(1, matchIdx)), IF(x <= INDEX(x_range, 1), INDEX(y_range, 1), IF(x >= INDEX(x_range, 8), INDEX(y_range, 8), FORECAST(x, OFFSET(INDEX(y_range, 1), 0, colIdx - 1, 1, 2), OFFSET(INDEX(x_range, 1), 0, colIdx - 1, 1, 2)))))} -> 87 | Z2: {=LET(x, 0.5*M2 + 0.5*K2, x_range, Percentiles!$B$57:$I$57, y_range, Translation_Matrix!$B$31:$I$31, matchIdx, IFNA(MATCH(x, x_range, 1), 1), colIdx, MIN(7, MAX(1, matchIdx)), IF(x <= INDEX(x_range, 1), INDEX(y_range, 1), IF(x >= INDEX(x_range, 8), INDEX(y_range, 8), FORECAST(x, OFFSET(INDEX(y_range, 1), 0, colIdx - 1, 1, 2), OFFSET(INDEX(x_range, 1), 0, colIdx - 1, 1, 2)))))} -> 86 | AA2: {=LET(x, 0.5*M2 + 0.5*K2, x_range, Percentiles!$B$57:$I$57, y_range, Translation_Matrix!$B$32:$I$32, matchIdx, IFNA(MATCH(x, x_range, 1), 1), colIdx, MIN(7, MAX(1, matchIdx)), IF(x <= INDEX(x_range, 1), INDEX(y_range, 1), IF(x >= INDEX(x_range, 8), INDEX(y_range, 8), FORECAST(x, OFFSET(INDEX(y_range, 1), 0, colIdx - 1, 1, 2), OFFSET(INDEX(x_range, 1), 0, colIdx - 1, 1, 2)))))} -> 80.49 | AB2: {=LET(x, 1*K2, x_range, Percentiles!$B$55:$I$55, y_range, Translation_Matrix!$B$24:$I$24, matchIdx, IFNA(MATCH(x, x_range, 1), 1), colIdx, MIN(7, MAX(1, matchIdx)), IF(x <= INDEX(x_range, 1), INDEX(y_range, 1), IF(x >= INDEX(x_range, 8), INDEX(y_range, 8), FORECAST(x, OFFSET(INDEX(y_range, 1), 0, colIdx - 1, 1, 2), OFFSET(INDEX(x_range, 1), 0, colIdx - 1, 1, 2)))))} -> 94.076923 | AC2: {=LET(x, 0.55*L2 + 0.3*A2 + 0.15*B2, x_range, Percentiles!$B$56:$I$56, y_range, Translation_Matrix!$B$26:$I$26, matchIdx, IFNA(MATCH(x, x_range, 1), 1), colIdx, MIN(7, MAX(1, matchIdx)), IF(x <= INDEX(x_range, 1), INDEX(y_range, 1), IF(x >= INDEX(x_range, 8), INDEX(y_range, 8), FORECAST(x, OFFSET(INDEX(y_range, 1), 0, colIdx - 1, 1, 2), OFFSET(INDEX(x_range, 1), 0, colIdx - 1, 1, 2)))))} -> 88.6 | AD2: {=LET(x, 0.55*L2 + 0.25*C2 + 0.2*D2, x_range, Percentiles!$B$56:$I$56, y_range, Translation_Matrix!$B$27:$I$27, matchIdx, IFNA(MATCH(x, x_range, 1), 1), colIdx, MIN(7, MAX(1, matchIdx)), IF(x <= INDEX(x_range, 1), INDEX(y_range, 1), IF(x >= INDEX(x_range, 8), INDEX(y_range, 8), FORECAST(x, OFFSET(INDEX(y_range, 1), 0, colIdx - 1, 1, 2), OFFSET(INDEX(x_range, 1), 0, colIdx - 1, 1, 2)))))} -> 91.875 | AG2: {=LET(x, 0.6*O2 + 0.25*D2 + 0.15*B2, x_range, Percentiles!$B$59:$I$59, y_range, Translation_Matrix!$B$36:$I$36, matchIdx, IFNA(MATCH(x, x_range, 1), 1), colIdx, MIN(7, MAX(1, matchIdx)), IF(x <= INDEX(x_range, 1), INDEX(y_range, 1), IF(x >= INDEX(x_range, 8), INDEX(y_range, 8), FORECAST(x, OFFSET(INDEX(y_range, 1), 0, colIdx - 1, 1, 2), OFFSET(INDEX(x_range, 1), 0, colIdx - 1, 1, 2)))))} -> 84 | AH2: {=LET(x, 0.65*O2 + 0.2*A2 + 0.15*L2, x_range, Percentiles!$B$59:$I$59, y_range, Translation_Matrix!$B$37:$I$37, matchIdx, IFNA(MATCH(x, x_range, 1), 1), colIdx, MIN(7, MAX(1, matchIdx)), IF(x <= INDEX(x_range, 1), INDEX(y_range, 1), IF(x >= INDEX(x_range, 8), INDEX(y_range, 8), FORECAST(x, OFFSET(INDEX(y_range, 1), 0, colIdx - 1, 1, 2), OFFSET(INDEX(x_range, 1), 0, colIdx - 1, 1, 2)))))} -> 82.89 | AI2: {=LET(x, 0.6*C2 + 0.3*D2 + 0.1*E2, x_range, Percentiles!$B$47:$I$47, y_range, Translation_Matrix!$B$6:$I$6, matchIdx, IFNA(MATCH(x, x_range, 1), 1), colIdx, MIN(7, MAX(1, matchIdx)), IF(x <= INDEX(x_range, 1), INDEX(y_range, 1), IF(x >= INDEX(x_range, 8), INDEX(y_range, 8), FORECAST(x, OFFSET(INDEX(y_range, 1), 0, colIdx - 1, 1, 2), OFFSET(INDEX(x_range, 1), 0, colIdx - 1, 1, 2)))))} -> 81.5 | AJ2: {=LET(x, 0.5*C2 + 0.25*M2 + 0.15*D2 + 0.1*E2, x_range, Percentiles!$B$47:$I$47, y_range, Translation_Matrix!$B$7:$I$7, matchIdx, IFNA(MATCH(x, x_range, 1), 1), colIdx, MIN(7, MAX(1, matchIdx)), IF(x <= INDEX(x_range, 1), INDEX(y_range, 1), IF(x >= INDEX(x_range, 8), INDEX(y_range, 8), FORECAST(x, OFFSET(INDEX(y_range, 1), 0, colIdx - 1, 1, 2), OFFSET(INDEX(x_range, 1), 0, colIdx - 1, 1, 2)))))} -> 76.325 | AK2: {=LET(x, 1*B2, x_range, Percentiles!$B$46:$I$46, y_range, Translation_Matrix!$B$4:$I$4, matchIdx, IFNA(MATCH(x, x_range, 1), 1), colIdx, MIN(7, MAX(1, matchIdx)), IF(x <= INDEX(x_range, 1), INDEX(y_range, 1), IF(x >= INDEX(x_range, 8), INDEX(y_range, 8), FORECAST(x, OFFSET(INDEX(y_range, 1), 0, colIdx - 1, 1, 2), OFFSET(INDEX(x_range, 1), 0, colIdx - 1, 1, 2)))))} -> 91.12 | AL2: {=LET(x, 1*D2, x_range, Percentiles!$B$48:$I$48, y_range, Translation_Matrix!$B$9:$I$9, matchIdx, IFNA(MATCH(x, x_range, 1), 1), colIdx, MIN(7, MAX(1, matchIdx)), IF(x <= INDEX(x_range, 1), INDEX(y_range, 1), IF(x >= INDEX(x_range, 8), INDEX(y_range, 8), FORECAST(x, OFFSET(INDEX(y_range, 1), 0, colIdx - 1, 1, 2), OFFSET(INDEX(x_range, 1), 0, colIdx - 1, 1, 2)))))} -> 82.666667 | AM2: =SQRT(SUMSQ(Q2:AL2)) -> 376.80657 | AN2: =66 + (0.24 * A2) -> 75.6
A3: Stat Rank (1=best) | R3: =IFERROR(RANK(R2,$R$2:$AL$2,0),22) -> 13 | S3: =IFERROR(RANK(S2,$R$2:$AL$2,0),22) -> 6 | T3: =IFERROR(RANK(T2,$R$2:$AL$2,0),22) -> 22 | U3: =IFERROR(RANK(U2,$R$2:$AL$2,0),22) -> 11 | V3: =IFERROR(RANK(V2,$R$2:$AL$2,0),22) -> 5 | W3: =IFERROR(RANK(W2,$R$2:$AL$2,0),22) -> 4 | X3: =IFERROR(RANK(X2,$R$2:$AL$2,0),22) -> 8 | Y3: =IFERROR(RANK(Y2,$R$2:$AL$2,0),22) -> 9 | ... AL3: =IFERROR(RANK(AL2,$R$2:$AL$2,0),22) -> 15
